Workbook

Sheet DMKTKT
A1: Phụ lục
A2: ĐỊNH MỨC KINH TẾ - KỸ THUẬT NGHỀ CHĂM SÓC SẮC ĐẸP
A3: Trình độ đào tạo: Chương trình đào tạo nghề khác (đào tạo dưới 3 tháng theo CTĐT ban hành kèm Quyết định số 2235/QĐ-CĐKT ngày 07/10/2026)
A4: ="Thời gian đào tạo: "&THAM_SO!$B$10&" giờ (2,5 tháng)" -> Thời gian đào tạo: 244 giờ (2,5 tháng)
A5: Căn cứ Quyết định số 2235/QĐ-CĐKT ngày 07/10/2026 của Hiệu trưởng Trường Cao đẳng Kon Tum ban hành Chương trình, giáo trình đào tạo nghề Chăm sóc sắc đẹp, đào tạo dưới 3 tháng năm 2026. Đào tạo tại Cơ sở 1 (Trụ sở chính).
A6: =" Định mức kinh tế - kỹ thuật về đào tạo cho 01 người học, trong điều kiện lớp học lý thuyết "&THAM_SO!$B$4&" người học và lớp học thực hành "&THAM_SO!$B$5&" người học." -> Định mức kinh tế - kỹ thuật về đào tạo cho 01 người học, trong điều kiện lớp học lý thuyết 35 người học và lớp học thực hành 18 người học.
A8: I. ĐỊNH MỨC LAO ĐỘNG
A9: STT | B9: Định mức lao động | C9: ĐVT | D9: Số giờ CTĐT | E9: Mẫu số (sĩ số) | F9: Định mức (giờ/người học) | G9: Ghi chú
B10: Tổng cộng (1)+(2) | C10: Giờ | F10: =F11+F14 -> 14.34
A11: 1 | B11: Định mức lao động trực tiếp (ĐMLĐTT) | C11: Giờ | D11: =THAM_SO!$B$10 -> 244 | F11: =F12+F13 -> 12.47
A12: 1.1 | B12: Định mức giờ dạy lý thuyết | C12: Giờ | D12: =THAM_SO!$B$6 -> 40 | E12: =THAM_SO!$B$4 -> 35 | F12: =ROUND(D12/E12,2) -> 1.14 | G12: Giờ LT ÷ sĩ số lớp LT
A13: 1.2 | B13: Định mức giờ dạy thực hành (bao gồm cả kiểm tra) | C13: Giờ | D13: =THAM_SO!$B$9 -> 204 | E13: =THAM_SO!$B$5 -> 18 | F13: =ROUND(D13/E13,2) -> 11.33 | G13: ="("&THAM_SO!$B$7&" TH + "&THAM_SO!$B$8&" KT) ÷ sĩ số lớp TH" -> (200 TH + 4 KT) ÷ sĩ số lớp TH
A14: 2 | B14: Định mức lao động gián tiếp (ĐMLĐGT) | C14: Giờ | F14: =ROUND(F11*THAM_SO!$B$11,2) -> 1.87 | G14: 15% ĐMLĐTT
A16: II. ĐỊNH MỨC THIẾT BỊ
A17: STT | B17: Tên thiết bị, dụng cụ | C17: Thông số kỹ thuật cơ bản | D17: ĐVT | E17: Số lượng sử dụng đồng thời/lớp | F17: Giờ sử dụng theo CTĐT (giờ) | G17: Mẫu số (sĩ số lớp) | H17: Định mức thiết bị (giờ/người học) | I17: Ghi chú
A18: 1 | B18: Ti vi (máy chiếu) 65 inch trở lên | C18: Loại thông dụng trên thị trường | D18: Bộ | E18: 1 | F18: =THAM_SO!$B$6 -> 40 | G18: =THAM_SO!$B$4 -> 35 | H18: =IF(OR(E18="",F18=""),"",ROUND(E18*F18/G18,2)) -> 1.14 | I18: Toàn bộ giờ lý thuyết (40 giờ); 20%/năm
A19: 2 | B19: Máy vi tính (laptop) | C19: Thông số thông dụng | D19: Bộ | E19: 1 | F19: =THAM_SO!$B$6 -> 40 | G19: =THAM_SO!$B$4 -> 35 | H19: =IF(OR(E19="",F19=""),"",ROUND(E19*F19/G19,2)) -> 1.14 | I19: Toàn bộ giờ lý thuyết; 14,29%/năm
A20: 3 | B20: Bút trình chiếu | C20: Loại thông dụng trên thị trường | D20: Cái | E20: 1 | F20: =THAM_SO!$B$6 -> 40 | G20: =THAM_SO!$B$4 -> 35 | H20: =IF(OR(E20="",F20=""),"",ROUND(E20*F20/G20,2)) -> 1.14 | I20: Toàn bộ giờ lý thuyết; tiêu hao 80% -> 1 năm
A21: 4 | B21: Bảng từ chống lóa (phòng học lý thuyết) | C21: Loại thông dụng | D21: Cái | E21: 1 | F21: =THAM_SO!$B$6 -> 40 | G21: =THAM_SO!$B$4 -> 35 | H21: =IF(OR(E21="",F21=""),"",ROUND(E21*F21/G21,2)) -> 1.14 | I21: Toàn bộ giờ lý thuyết; tiêu hao 50% -> 2 năm
A22: 5 | B22: Giường spa | C22: Loại thông dụng | D22: Cái | E22: 9 | F22: 95 | G22: =THAM_SO!$B$5 -> 18 | H22: =IF(OR(E22="",F22=""),"",ROUND(E22*F22/G22,2)) -> 47.5 | I22: Theo cặp thực hành (9 cái/lớp, một người làm, một người làm mẫu). MĐ1: bài 2 (18) + bài 3-6 (75) + kiểm tra (2) = 95 giờ; tiêu hao 50% -> 2 năm
A23: 6 | B23: Ga trải giường spa | C23: Loại thông dụng | D23: Cái | E23: 9 | F23: 95 | G23: =THAM_SO!$B$5 -> 18 | H23: =IF(OR(E23="",F23=""),"",ROUND(E23*F23/G23,2)) -> 47.5 | I23: Theo giường (9 cái/lớp), đi kèm giường spa, 95 giờ
A24: 7 | B24: Tủ hấp khăn | C24: Loại thông dụng | D24: Cái | E24: 1 | F24: 77 | G24: =THAM_SO!$B$5 -> 18 | H24: =IF(OR(E24="",F24=""),"",ROUND(E24*F24/G24,2)) -> 4.28 | I24: Dùng chung cả lớp thực hành (01 cái/lớp). MĐ1 bài 3-6 (75) + kiểm tra (2) = 77 giờ
A25: 8 | B25: Máy xông hơi (mặt) | C25: Loại thông dụng | D25: Cái | E25: =1*THAM_SO!$B$20 -> 2 | F25: 42 | G25: =THAM_SO!$B$5 -> 18 | H25: =IF(OR(E25="",F25=""),"",ROUND(E25*F25/G25,2)) -> 4.67 | I25: Theo nhóm, 01 máy/nhóm x 02 nhóm = 02 máy/lớp. MĐ1 bài 4 mặt nạ (20) + bài 5 chăm sóc, điều trị da mặt (22) = 42 giờ.
A26: 9 | B26: Máy soi da | C26: Loại thông dụng | D26: Cái | E26: =1*THAM_SO!$B$20 -> 2 | F26: 20 | G26: =THAM_SO!$B$5 -> 18 | H26: =IF(OR(E26="",F26=""),"",ROUND(E26*F26/G26,2)) -> 2.22 | I26: 01 máy/nhóm x 02 nhóm = 02 máy/lớp. MĐ1 bài 2 phân loại da, soi da (10) + bài 5 thăm khám, soi da (10) = 20 giờ
A27: 10 | B27: Đèn soi da (đèn LED) | C27: Loại thông dụng | D27: Cái | E27: =1*THAM_SO!$B$20 -> 2 | F27: 20 | G27: =THAM_SO!$B$5 -> 18 | H27: =IF(OR(E27="",F27=""),"",ROUND(E27*F27/G27,2)) -> 2.22 | I27: 01 cái/nhóm x 02 nhóm = 02 cái/lớp . Như máy soi da, 20 giờ
A28: 11 | B28: Bộ bàn trang điểm | C28: Loại thông dụng (CTĐT: bàn + ghế 25 bộ) | D28: Bộ | E28: 9 | F28: 102 | G28: =THAM_SO!$B$5 -> 18 | H28: =IF(OR(E28="",F28=""),"",ROUND(E28*F28/G28,2)) -> 51 | I28: Theo cặp thực hành (9 bộ/lớp, một người trang điểm, một người làm mẫu). MĐ2: 100 giờ thực hành + 2 giờ kiểm tra = 102 giờ.
A29: 12 | B29: Gương trang điểm có đèn | C29: Loại thông dụng | D29: Cái | E29: 5 | F29: 102 | G29: =THAM_SO!$B$5 -> 18 | H29: =IF(OR(E29="",F29=""),"",ROUND(E29*F29/G29,2)) -> 28.33 | I29: Theo cặp (5 cái/lớp), MĐ2 102 giờ
A30: 13 | B30: Đèn LED trang điểm chuyên dụng | C30: Loại thông dụng | D30: Cái | E30: 5 | F30: 102 | G30: =THAM_SO!$B$5 -> 18 | H30: =IF(OR(E30="",F30=""),"",ROUND(E30*F30/G30,2)) -> 28.33 | I30: Theo cặp (5 cái/lớp), MĐ2 102 giờ
A31: 14 | B31: Bộ cọ trang điểm | C31: Loại thông dụng | D31: Bộ | E31: =THAM_SO!$B$5 -> 18 | F31: 102 | G31: =THAM_SO!$B$5 -> 18 | H31: =IF(OR(E31="",F31=""),"",ROUND(E31*F31/G31,2)) -> 102 | I31: Cá nhân (18 bộ/lớp) để bảo đảm vệ sinh, MĐ2 102 giờ
A32: 15 | B32: Cốp đựng đồ trang điểm | C32: Loại thông dụng | D32: Cái | E32: 9 | F32: 102 | G32: =THAM_SO!$B$5 -> 18 | H32: =IF(OR(E32="",F32=""),"",ROUND(E32*F32/G32,2)) -> 51 | I32: Theo cặp (9 cái/lớp), MĐ2 102 giờ
A33: 16 | B33: Nhíp gắp phụ kiện | C33: Loại thông dụng | D33: Cái | E33: 9 | F33: 15 | G33: =THAM_SO!$B$5 -> 18 | H33: =IF(OR(E33="",F33=""),"",ROUND(E33*F33/G33,2)) -> 7.5 | I33: Theo cặp (9 cái/lớp). MĐ2 bài 6 trang điểm mắt, gắn mi giả: 15 giờ
A34: 17 | B34: Gương cầm tay | C34: Loại thông dụng | D34: Cái | E34: =THAM_SO!$B$5 -> 18 | F34: =THAM_SO!$B$9 -> 204 | G34: =THAM_SO!$B$5 -> 18 | H34: =IF(OR(E34="",F34=""),"",ROUND(E34*F34/G34,2)) -> 204 | I34: Cá nhân (18 cái/lớp), toàn bộ giờ thực hành và kiểm tra (204 giờ)
A35: 18 | B35: Ổ cắm điện di động | C35: Loại thông dụng | D35: Cái | E35: =1*THAM_SO!$B$20 -> 2 | F35: =THAM_SO!$B$9 -> 204 | G35: =THAM_SO!$B$5 -> 18 | H35: =IF(OR(E35="",F35=""),"",ROUND(E35*F35/G35,2)) -> 22.67 | I35: Theo nhóm, 01 ổ cắm/nhóm x 02 nhóm = 02 cái/lớp, 204 giờ
A36: 19 | B36: Tủ/kệ đựng mỹ phẩm | C36: Loại thông dụng | D36: Cái | E36: =1*THAM_SO!$B$20 -> 2 | F36: =THAM_SO!$B$9 -> 204 | G36: =THAM_SO!$B$5 -> 18 | H36: =IF(OR(E36="",F36=""),"",ROUND(E36*F36/G36,2)) -> 22.67 | I36: Dùng chung theo nhóm, 01 tủ/nhóm x 02 nhóm = 02 cái/lớp, 204 giờ.
A37: 20 | B37: Camera ghi hình cận cảnh | C37: Loại thông dụng | D37: Cái | E37: 1 | F37: 60 | G37: =THAM_SO!$B$5 -> 18 | H37: =IF(OR(E37="",F37=""),"",ROUND(E37*F37/G37,2)) -> 3.33 | I37: Dùng chung cả lớp thực hành (01 cái/lớp). 60 giờ: trình chiếu thao tác mẫu của giáo viên (khoảng 30 giờ/mô đun).
A38: 21 | B38: Chân máy ảnh/chân máy quay | C38: Loại thông dụng | D38: Cái | E38: 1 | F38: 60 | G38: =THAM_SO!$B$5 -> 18 | H38: =IF(OR(E38="",F38=""),"",ROUND(E38*F38/G38,2)) -> 3.33 | I38: Dùng chung (01 cái/lớp), đi kèm camera; 60 giờ.
A39: 22 | B39: Ti vi (phòng thực hành) | C39: CTĐT: ti vi; dùng giá ti vi 65 inch | D39: Cái | E39: 1 | F39: =THAM_SO!$B$9 -> 204 | G39: =THAM_SO!$B$5 -> 18 | H39: =IF(OR(E39="",F39=""),"",ROUND(E39*F39/G39,2)) -> 11.33 | I39: Dùng chung cả lớp thực hành (01 cái/lớp), 204 giờ; 20%/năm
A40: 23 | B40: Máy vi tính (laptop) – phòng thực hành | C40: CTĐT ghi laptop; dùng giá máy vi tính | D40: Cái | E40: 1 | F40: =THAM_SO!$B$9 -> 204 | G40: =THAM_SO!$B$5 -> 18 | H40: =IF(OR(E40="",F40=""),"",ROUND(E40*F40/G40,2)) -> 11.33 | I40: Dùng chung cả lớp thực hành, 204 giờ; 14,29%/năm
A41: 24 | B41: Bảng từ chống lóa (phòng thực hành) | C41: Loại thông dụng | D41: Cái | E41: 1 | F41: =THAM_SO!$B$9 -> 204 | G41: =THAM_SO!$B$5 -> 18 | H41: =IF(OR(E41="",F41=""),"",ROUND(E41*F41/G41,2)) -> 11.33 | I41: Dùng chung cả lớp thực hành, 204 giờ; tiêu hao 50% -> 2 năm
A42: 25 | B42: Máy điện di tinh chất | C42: Loại thông dụng | D42: Cái | E42: =1*THAM_SO!$B$20 -> 2 | F42: 12 | G42: =THAM_SO!$B$5 -> 18 | H42: =IF(OR(E42="",F42=""),"",ROUND(E42*F42/G42,2)) -> 1.33 | I42: 01 máy/nhóm x 02 nhóm = 02 máy/lớp. MĐ1 bài 5 (8) + bài 6 chăm sóc vùng mắt (4) = 12 giờ.
...

Sheet DMCPDT
A1: Phụ lục
A2: ĐỊNH MỨC CHI PHÍ ĐÀO TẠO NGHỀ CHĂM SÓC SẮC ĐẸP
A3: Trình độ đào tạo: Chương trình đào tạo nghề khác (đào tạo dưới 3 tháng theo CTĐT ban hành kèm Quyết định số 2235/QĐ-CĐKT ngày 07/10/2026)
A4: I. CHI PHÍ LAO ĐỘNG
A5: STT | B5: Nội dung | C5: ĐVT | D5: Định mức (giờ/người học) | E5: Đơn giá (đồng/giờ) | F5: Thành tiền (đồng) | G5: Ghi chú
A6: 1.1 | B6: Lao động trực tiếp – lý thuyết | C6: Giờ | D6: =DMKTKT!F12 -> 1.14 | E6: =THAM_SO!$B$12 -> 200000 | F6: =D6*E6 -> 228000
A7: 1.2 | B7: Lao động trực tiếp – thực hành (gồm kiểm tra) | C7: Giờ | D7: =DMKTKT!F13 -> 11.33 | E7: =THAM_SO!$B$12 -> 200000 | F7: =D7*E7 -> 2266000
A8: 2 | B8: Lao động gián tiếp (15% trực tiếp) | C8: Giờ | D8: =DMKTKT!F14 -> 1.87 | E8: =THAM_SO!$B$12 -> 200000 | F8: =D8*E8 -> 374000 | G8: Đơn giá giờ gián tiếp = trực tiếp
B9: Cộng chi phí lao động | F9: =SUM(F6:F8) -> 2868000
A11: II. CHI PHÍ THIẾT BỊ, DỤNG CỤ (khấu hao, hao mòn, phân bổ)
A12: STT | B12: Tên thiết bị, dụng cụ | C12: Định mức (giờ/người học) | D12: Nguyên giá (đồng) | E12: Phân loại | F12: Tỷ lệ hao mòn/năm | G12: Số năm phân bổ (CCDC) | H12: Đơn giá (đồng/giờ) | I12: Thành tiền (đồng)
A13: 1 | B13: =DMKTKT!B18 -> Ti vi (máy chiếu) 65 inch trở lên | C13: =IF(DMKTKT!H18="","",DMKTKT!H18) -> 1.14 | D13: 25980000 | E13: TSCĐ | F13: 0.2 | G13: – | H13: =D13*F13/THAM_SO!$B$13 -> 2952.2727 | I13: =IF(C13="","",C13*H13) -> 3365.5909
A14: 2 | B14: =DMKTKT!B19 -> Máy vi tính (laptop) | C14: =IF(DMKTKT!H19="","",DMKTKT!H19) -> 1.14 | D14: 16690000 | E14: TSCĐ | F14: 0.1429 | G14: – | H14: =D14*F14/THAM_SO!$B$13 -> 1355.1142 | I14: =IF(C14="","",C14*H14) -> 1544.8302
A15: 3 | B15: =DMKTKT!B20 -> Bút trình chiếu | C15: =IF(DMKTKT!H20="","",DMKTKT!H20) -> 1.14 | D15: 250000 | E15: CCDC | F15: – | G15: 1 | H15: =D15/(G15*THAM_SO!$B$13) -> 142.04545 | I15: =IF(C15="","",C15*H15) -> 161.93182
A16: 4 | B16: =DMKTKT!B21 -> Bảng từ chống lóa (phòng học lý thuyết) | C16: =IF(DMKTKT!H21="","",DMKTKT!H21) -> 1.14 | D16: 5000000 | E16: CCDC | F16: – | G16: 2 | H16: =D16/(G16*THAM_SO!$B$13) -> 1420.4545 | I16: =IF(C16="","",C16*H16) -> 1619.3182
A17: 5 | B17: =DMKTKT!B22 -> Giường spa | C17: =IF(DMKTKT!H22="","",DMKTKT!H22) -> 47.5 | D17: 975000 | E17: CCDC | F17: – | G17: 2 | H17: =D17/(G17*THAM_SO!$B$13) -> 276.98864 | I17: =IF(C17="","",C17*H17) -> 13156.96
A18: 6 | B18: =DMKTKT!B23 -> Ga trải giường spa | C18: =IF(DMKTKT!H23="","",DMKTKT!H23) -> 47.5 | D18: 380000 | E18: CCDC | F18: – | G18: 2 | H18: =D18/(G18*THAM_SO!$B$13) -> 107.95455 | I18: =IF(C18="","",C18*H18) -> 5127.8409
A19: 7 | B19: =DMKTKT!B24 -> Tủ hấp khăn | C19: =IF(DMKTKT!H24="","",DMKTKT!H24) -> 4.28 | D19: 537000 | E19: CCDC | F19: – | G19: 2 | H19: =D19/(G19*THAM_SO!$B$13) -> 152.55682 | I19: =IF(C19="","",C19*H19) -> 652.94318
A20: 8 | B20: =DMKTKT!B25 -> Máy xông hơi (mặt) | C20: =IF(DMKTKT!H25="","",DMKTKT!H25) -> 4.67 | D20: 1520000 | E20: CCDC | F20: – | G20: 2 | H20: =D20/(G20*THAM_SO!$B$13) -> 431.81818 | I20: =IF(C20="","",C20*H20) -> 2016.5909
A21: 9 | B21: =DMKTKT!B26 -> Máy soi da | C21: =IF(DMKTKT!H26="","",DMKTKT!H26) -> 2.22 | D21: 1500000 | E21: CCDC | F21: – | G21: 2 | H21: =D21/(G21*THAM_SO!$B$13) -> 426.13636 | I21: =IF(C21="","",C21*H21) -> 946.02273
A22: 10 | B22: =DMKTKT!B27 -> Đèn soi da (đèn LED) | C22: =IF(DMKTKT!H27="","",DMKTKT!H27) -> 2.22 | D22: 294500 | E22: CCDC | F22: – | G22: 2 | H22: =D22/(G22*THAM_SO!$B$13) -> 83.664773 | I22: =IF(C22="","",C22*H22) -> 185.7358
A23: 11 | B23: =DMKTKT!B28 -> Bộ bàn trang điểm | C23: =IF(DMKTKT!H28="","",DMKTKT!H28) -> 51 | D23: 2400000 | E23: CCDC | F23: – | G23: 2 | H23: =D23/(G23*THAM_SO!$B$13) -> 681.81818 | I23: =IF(C23="","",C23*H23) -> 34772.727
A24: 12 | B24: =DMKTKT!B29 -> Gương trang điểm có đèn | C24: =IF(DMKTKT!H29="","",DMKTKT!H29) -> 28.33 | D24: 275000 | E24: CCDC | F24: – | G24: 2 | H24: =D24/(G24*THAM_SO!$B$13) -> 78.125 | I24: =IF(C24="","",C24*H24) -> 2213.2812
A25: 13 | B25: =DMKTKT!B30 -> Đèn LED trang điểm chuyên dụng | C25: =IF(DMKTKT!H30="","",DMKTKT!H30) -> 28.33 | D25: 207950 | E25: CCDC | F25: – | G25: 2 | H25: =D25/(G25*THAM_SO!$B$13) -> 59.076705 | I25: =IF(C25="","",C25*H25) -> 1673.643
A26: 14 | B26: =DMKTKT!B31 -> Bộ cọ trang điểm | C26: =IF(DMKTKT!H31="","",DMKTKT!H31) -> 102 | D26: 530000 | E26: CCDC | F26: – | G26: 2 | H26: =D26/(G26*THAM_SO!$B$13) -> 150.56818 | I26: =IF(C26="","",C26*H26) -> 15357.955
... A33: 21 | B33: =DMKTKT!B38 -> Chân máy ảnh/chân máy quay | C33: =IF(DMKTKT!H38="","",DMKTKT!H38) -> 3.33 | D33: 833000 | E33: CCDC | F33: – | G33: 2 | H33: =D33/(G33*THAM_SO!$B$13) -> 236.64773 | I33: =IF(C33="","",C33*H33) -> 788.03693
A34: 22 | B34: =DMKTKT!B39 -> Ti vi (phòng thực hành) | C34: =IF(DMKTKT!H39="","",DMKTKT!H39) -> 11.33 | D34: 25980000 | E34: TSCĐ | F34: 0.2 | G34: – | H34: =D34*F34/THAM_SO!$B$13 -> 2952.2727 | I34: =IF(C34="","",C34*H34) -> 33449.25
A35: 23 | B35: =DMKTKT!B40 -> Máy vi tính (laptop) – phòng thực hành | C35: =IF(DMKTKT!H40="","",DMKTKT!H40) -> 11.33 | D35: 16690000 | E35: TSCĐ | F35: 0.1429 | G35: – | H35: =D35*F35/THAM_SO!$B$13 -> 1355.1142 | I35: =IF(C35="","",C35*H35) -> 15353.444
A36: 24 | B36: =DMKTKT!B41 -> Bảng từ chống lóa (phòng thực hành) | C36: =IF(DMKTKT!H41="","",DMKTKT!H41) -> 11.33 | D36: 5000000 | E36: CCDC | F36: – | G36: 2 | H36: =D36/(G36*THAM_SO!$B$13) -> 1420.4545 | I36: =IF(C36="","",C36*H36) -> 16093.75
A37: 25 | B37: =DMKTKT!B42 -> Máy điện di tinh chất | C37: =IF(DMKTKT!H42="","",DMKTKT!H42) -> 1.33 | D37: 450000 | E37: CCDC | G37: 2 | H37: =IF(OR(D37="",C37=""),"",IF(E37="TSCĐ",D37*F37/THAM_SO!$B$13,IF(E37="CCDC",D37/(G37*THAM_SO!$B$13),""))) -> 127.84091 | I37: =IF(OR(C37="",H37=""),"",C37*H37) -> 170.02841
B38: Cộng chi phí thiết bị, dụng cụ (phần đã có giá) | I38: =SUM(I13:I37) -> 163144.47
A40: III. CHI PHÍ VẬT TƯ
A41: STT | B41: Tên vật tư | C41: ĐVT | D41: Tiêu hao (đơn vị/người học) | E41: Đơn giá (đồng) | F41: Thành tiền (đồng) | G41: Ghi chú
A42: 1 | B42: =DMKTKT!B46 -> Tài liệu học tập - Giáo trình mô đun Chăm sóc da | C42: Quyển | D42: =IF(DMKTKT!H46="","",DMKTKT!H46) -> 1 | E42: =THAM_SO!$B$17*THAM_SO!$B$16 -> 52000 | F42: =IF(OR(D42="",E42=""),"",D42*E42) -> 52000 | G42: Số trang x 500 đồng/trang
A43: 2 | B43: =DMKTKT!B47 -> Tài liệu học tập - Giáo trình mô đun Kỹ thuật trang điểm căn bản | C43: Quyển | D43: =IF(DMKTKT!H47="","",DMKTKT!H47) -> 1 | E43: =THAM_SO!$B$18*THAM_SO!$B$16 -> 33500 | F43: =IF(OR(D43="",E43=""),"",D43*E43) -> 33500 | G43: Số trang x 500 đồng/trang
A44: 3 | B44: =DMKTKT!B48 -> Vở | C44: Quyển | D44: =IF(DMKTKT!H48="","",DMKTKT!H48) -> 1 | E44: 15000 | F44: =IF(OR(D44="",E44=""),"",D44*E44) -> 15000
A45: 4 | B45: =DMKTKT!B49 -> Bút | C45: Cây | D45: =IF(DMKTKT!H49="","",DMKTKT!H49) -> 1 | E45: 5000 | F45: =IF(OR(D45="",E45=""),"",D45*E45) -> 5000
A46: 5 | B46: =DMKTKT!B50 -> Hồ sơ học nghề | C46: Tờ | D46: =IF(DMKTKT!H50="","",DMKTKT!H50) -> 1 | E46: 1000 | F46: =IF(OR(D46="",E46=""),"",D46*E46) -> 1000
A47: 6 | B47: =DMKTKT!B51 -> Giấy thi, giấy kiểm tra | C47: Tờ | D47: =IF(DMKTKT!H51="","",DMKTKT!H51) -> 2 | E47: 1000 | F47: =IF(OR(D47="",E47=""),"",D47*E47) -> 2000
A48: 7 | B48: =DMKTKT!B52 -> Chứng chỉ tốt nghiệp | C48: Cái | D48: =IF(DMKTKT!H52="","",DMKTKT!H52) -> 1 | E48: 50000 | F48: =IF(OR(D48="",E48=""),"",D48*E48) -> 50000
...

Sheet THUYET_MINH
A1: BẢNG THUYẾT MINH CƠ SỞ XÂY DỰNG ĐỊNH MỨC KINH TẾ - KỸ THUẬT VÀ ĐỊNH MỨC CHI PHÍ ĐÀO TẠO
A2: NGHỀ CHĂM SÓC SẮC ĐẸP
A4: 1. Thời gian đào tạo
A5: CTĐT nghề Chăm sóc sắc đẹp dưới 3 tháng (bản nhận được chưa ghi số, ngày Quyết định ban hành; Hội đồng thẩm định ngày 12/9/2026, chưa ban hành): 244 giờ, 2,5 tháng (lý thuyết 40; thực hành 200; kiểm tra 04 giờ tính vào thực hành), 2 mô đun: Chăm sóc da (330200053) 122 giờ, Kỹ thuật trang điểm căn bản (330200063) 122 giờ. Lao động trực tiếp = 40 ÷ 35 + 204 ÷ 18; gián tiếp = 15% trực tiếp; mỗi khoản làm tròn 2 chữ số thập phân (14,34 giờ). Giảng viên dạy thực hành cho cả lớp 18 người học (chia 02 nhóm để bố trí thiết bị, vật tư) nên giờ dạy không nhân theo số nhóm.
A6: 2. Định mức lao động
A7: Lao động trực tiếp: giờ lý thuyết ÷ sĩ số lớp lý thuyết + giờ thực hành (gồm kiểm tra) ÷ sĩ số lớp thực hành; lao động gián tiếp (quản lý, phục vụ, tuyển sinh, bế giảng) = 15% lao động trực tiếp. Mỗi thành phần làm tròn 2 chữ số thập phân trước khi cộng.
A8: 3. Định mức thiết bị
A9: Định mức (giờ/người học) = số lượng sử dụng đồng thời × giờ sử dụng ÷ sĩ số, làm tròn 2 chữ số thập phân. Thiết bị lý thuyết: 40 giờ ÷ 35. Giường spa, ga, bộ bàn trang điểm, gương có đèn, đèn LED, cốp, nhíp: theo cặp 09 cái/lớp (học viên làm mẫu cho nhau). Bộ cọ, gương cầm tay: cá nhân 18 cái/lớp. Máy xông hơi, máy soi da, đèn soi da, ổ cắm, tủ/kệ mỹ phẩm, máy hút mụn, máy điện di: 01 thiết bị/nhóm x 02 nhóm = 02 thiết bị/lớp (tệp nguồn: 2 đến 5). Tủ hấp khăn, camera, chân máy, ti vi, máy vi tính, bảng phòng thực hành: dùng chung 01 cái/lớp. Giờ T lấy theo tệp nguồn (MĐ1 theo bài chăm sóc da, MĐ2 102 giờ, 204 giờ cho thiết bị dùng suốt khóa).
A10: 4. Định mức vật tư
A11: Vật tư dùng chung theo mẫu của Trường: tài liệu học tập (03 giáo trình x số trang x 500 đồng/trang), vở, bút, hồ sơ học nghề, giấy thi 02 tờ, chứng chỉ, khen thưởng 03 bộ/lớp, khai giảng, bế giảng, hồ sơ tốt nghiệp 03 bộ/lớp; chia cho sĩ số lớp lý thuyết. Vật tư nghề: : mỹ phẩm dùng mọi buổi (sữa rửa mặt, gel tẩy tế bào chết, tinh dầu massage, kem lót, kem nền, che khuyết điểm, phấn phủ, má hồng, son màu sáng, chì kẻ, phấn mắt, mascara, tẩy trang, mút) 01 sản phẩm/nhóm; sản phẩm chỉ dùng ở một số bài hoặc thao tác mẫu (serum, kem dưỡng, kem chống nắng, mặt nạ, muối biển, son dưỡng, bóng, tối, lì, bảng màu mắt, mi giả...) 01 sản phẩm/lớp; bông tẩy trang, khăn ướt, khẩu trang, băng đô, dao lam, dao cạo râu 02/nhóm; bộ tỉa lông mày, kéo tỉa 01/nhóm; kẹp bấm lông mi theo cặp 09/lớp.
A12: 5. Định mức cơ sở vật chất
A13: Đlt = 1,7 m²/người học × 40 giờ = 68 m²·giờ; Đth = 4,0 m²/người học × 204 giờ = 816 m²·giờ (Cơ sở 1). Không tính khu chức năng, hạ tầng kỹ thuật khác (sơ cấp, dưới 3 tháng). CTĐT ghi phòng thực hành 50 m² (khoảng 2,8 m²/người học với lớp 18).
... A23: Kết quả là định mức chi phí đào tạo (bảng chi phí đã tính) cho 01 người học/khóa, 04 thành phần, không gồm chi phí quản lý chung theo quyết định của Trường; chưa phải giá dịch vụ đào tạo hay mức thu học phí.

Sheet THAM_SO
A1: THAM SỐ TÍNH TOÁN (đổi ô nền vàng nhạt thì DMKTKT, DMCPDT tự tính lại)
A3: Tham số | B3: Giá trị | C3: ĐVT | D3: Nguồn / ghi chú
A4: Sĩ số lớp lý thuyết | B4: 35 | C4: người | D4: Khóa tuyển sinh trước 10/11/2026 (file nguồn, Thong_so C12). Khóa từ 10/11/2026: 45
A5: Sĩ số lớp thực hành | B5: 18 | C5: người | D5: Như trên; QĐ 1400/QĐ-CĐKT Điều 5 khoản 1. Khóa từ 10/11/2026: 25
A6: Giờ lý thuyết theo CTĐT | B6: 40 | C6: giờ | D6: CTĐT dưới 3 tháng, 2 mô đun: Chăm sóc da 20 + Kỹ thuật trang điểm căn bản 20 (file nguồn, Thong_so D6:D7)
A7: Giờ thực hành theo CTĐT (không gồm kiểm tra) | B7: 200 | C7: giờ | D7: CTĐT: 100 + 100
A8: Giờ kiểm tra kết thúc mô đun (tính vào thực hành) | B8: 4 | C8: giờ | D8: CTĐT: 2 + 2 (tự luận + thực hành)
A9: Giờ thực hành gồm kiểm tra | B9: =B7+B8 -> 204 | C9: giờ | D9: 200 + 4
A10: Tổng giờ đào tạo | B10: =B6+B9 -> 244 | C10: giờ | D10: CTĐT: 244 giờ (40 + 200 + 4), toàn khóa 2,5 tháng (MĐ1 122 giờ; MĐ2 122 giờ)
A11: Tỷ lệ lao động gián tiếp / trực tiếp | B11: 0.15 | C11: % | D11: Phòng TC-KT xác nhận 30/9/2026
A12: Đơn giá giờ giảng (trực tiếp = gián tiếp) | B12: 200000 | C12: đồng/giờ | D12: Như hồ sơ nghề Kỹ thuật trang điểm: 200.000 đồng/giờ (điểm a khoản 1 Điều 20 Quy chế chi tiêu nội bộ 2026, QĐ 1334/QĐ-CĐKT). Thong_so C16 của file nguồn còn ghi 120.000
A13: Số giờ sử dụng tài sản/năm | B13: 1760 | C13: giờ | D13: 44 tuần x 40 giờ (Phòng TC-KT 30/9/2026)
A14: Diện tích lý thuyết/người học (Slt) | B14: 1.7 | C14: m2 | D14: Bảng giá đầu vào nghề Chăm sóc sắc đẹp, sheet Cơ sở vật chất, Cơ sở 1 (ghi chú áp dụng sơ cấp)
A15: Diện tích thực hành/người học (Sth) | B15: 4 | C15: m2 | D15: Như trên; không sử dụng khu chức năng, hạ tầng khác
A16: Đơn giá tài liệu học tập | B16: 500 | C16: đồng/trang | D16: Như hồ sơ nghề Kỹ thuật trang điểm: số trang x 500 đồng/trang (Can_xac_nhan mục 8 của file nguồn ghi 50.000 đồng/cuốn)
A17: Số trang giáo trình Chăm sóc da (330200053) | B17: 104 | C17: trang | D17: Thuộc tính tệp Word (Pages = 104); mục lục ghi Tài liệu tham khảo trang 96. BCN xác nhận số trang bản in
A18: Số trang giáo trình Kỹ thuật trang điểm căn bản (330200063) | B18: 67 | C18: trang | D18: Thuộc tính tệp Word (Pages = 67); mục lục ghi Tài liệu tham khảo trang 58
A19: Số trang giáo trình Kỹ thuật trang điểm nâng cao | B19: 36 | C19: trang | D19: Thuộc tính tệp Word (Pages = 36); mục lục ghi Tài liệu tham khảo trang 31. Mô đun này không có trong CTĐT 2 mô đun của file nguồn – BCN xác nhận có phát giáo trình này không
A20: Số nhóm thực hành trong lớp | B20: 2 | C20: nhóm | D20: Theo yêu cầu 07/10/2026: lớp thực hành chia 02 nhóm (18 người học = 02 nhóm, mỗi nhóm 9 người)
