Workbook

Sheet Ke Hoach
A1: Phụ lục I
A2: KẾ HOẠCH THỰC HIỆN NHIỆM VỤ CÔNG TÁC QUÝ III NĂM 2026 VÀ DANH MỤC SẢN PHẨM/ CÔNG VIỆC CỦA CÁ NHÂN VIÊN CHỨC TRƯỜNG CAO ĐẲNG KON TUM
B4: Họ và tên: …............ Ngày sinh: …..............
B5: Chức vụ Đảng: …..............................................................................................................................
B6: Chức vụ chính quyền: …......................................................................................................................
B7: Chức vụ đoàn thể: …..............................................................................................................................
B8: Đơn vị công tác: …..................................................................................................................................
A10: STT | B10: Nhiệm vụ theo quý | C10: Cấp trình | D10: Độ khó, mới, phức tạp; phạm vi tác động | E10: Sản phẩm | F10: Số lượng | G10: Thời gian hoàn thành | H10: Điểm chấm công việc | I10: Hệ số quy đổi | J10: Ghi chú
A11: (1) | B11: (2) | C11: (3) | D11: (4) | E11: (5) | F11: (6) | G11: (7) | H11: (8) | I11: (9) | J11: (10)
A12: A | B12: Các nhiệm vụ theo kế hoạch (chương trình) công tác đã đề ra từ đầu năm
A13: I | B13: Trục (1) - Thực hiện mục tiêu phát triển Kinh tế - xã hội và nhiệm vụ chính trị được giao
A14: 1 | B14: Tổ chức thi và hoàn thiện hồ sơ lớp bồi dưỡng tiếng dân tộc thiểu số Bahnar khoá 1 năm 2026. | C14: Trường Cao đẳng Kon Tum | D14: Thường xuyên, nhiệm vụ chủ yếu là thống kê (mức độ thấp) | E14: Hồ sơ thi và hoàn thiện hồ sơ lớp bồi dưỡng | F14: 5 | G14: 46266 | H14: 100 | I14: 1
A15: 2
A16: 3
A17: 4
A18: 5
A19: 6
A20: 7
A21: 8
A22: 9
A23: 10
A24: 11
A25: 12
A26: 13
... A33: 20
A34: II | B34: Trục (2) - Hoàn thiện thể chế, đẩy mạnh phân cấp, phân quyền gắn với kiểm tra, giám sát
A35: 1
A36: 2
A37: 3
A38: 4
A39: 5
A40: 6
A41: 7
A42: 8
A43: 9
A44: 10
A45: 11
A46: 12
... A54: 20
A55: III | B55: Trục (3) - Thúc đẩy phát triển khoa học, công nghệ, đổi mới sáng tạo và chuyển đổi số
...

Sheet KPI
A1: Phụ lục II (Kèm theo Quyết định số: /QĐ-CĐKT ngày tháng năm 2026 của Hiệu trưởng Trường Cao đẳng Kon Tum)
A2: DANH MỤC SẢN PHẨM CÔNG TÁC TRỌNG TÂM QUÝ III NĂM 2026 CỦA TRƯỜNG CAO ĐẲNG KON TUM -----
A3: STT | B3: NHIỆM VỤ ĐỀ RA KẾ HOẠCH | K3: THỰC TẾ TRIỂN KHAI | R3: Ghi chú
B4: NỘI DUNG CÔNG VIỆC | C4: Người trực tiếp chỉ đạo | D4: Người phối hợp | E4: Đơn vị tham mưu | F4: Sản phẩm dự kiến hoàn thành | G4: Số lượng | H4: Thời gian hoàn thành | I4: Hệ số quy đổi | J4: Số lượng quy đổi | K4: Sản phẩm | L4: KPI (số lượng) | N4: KPI (chất lượng) | P4: KPI (tiến độ)
L5: Thực tế hoàn thành | M5: Quy đổi | N5: Thực tế hoàn thành | O5: Quy đổi | P5: Thực tế hoàn thành | Q5: Quy đổi
N6: Nhập tỷ lệ % mức độ đáp ứng | P6: Nhập tỷ lệ % mức độ đáp ứng
A7: A | B7: Các nhiệm vụ theo kế hoạch (chương trình) công tác đã đề ra từ đầu năm
A8: I | B8: Trục (1) Thực hiện mục tiêu phát triển Kinh tế - xã hội và nhiệm vụ chính trị được giao | J8: =SUM(J9:J28) -> 5 | M8: =SUM(M9:M28) -> 4 | O8: =SUM(O9:O28) -> 4 | Q8: =SUM(Q9:Q28) -> 4 | R8: =(M8+O8+Q8)/3 -> 4
A9: 1 | B9: ='Ke Hoach'!B14 -> Tổ chức thi và hoàn thiện hồ sơ lớp bồi dưỡng tiếng dân tộc thiểu số Bahnar khoá 1 năm 2026. | G9: ='Ke Hoach'!F14 -> 5 | H9: ='Ke Hoach'!G14 -> 46266 | I9: ='Ke Hoach'!I14 -> 1 | J9: =G9*I9 -> 5 | L9: 4 | M9: =IF(G9=0,0,MIN(L9,G9)*I9) -> 4 | N9: 100 | O9: =I9*L9*N9/100 -> 4 | P9: 100 | Q9: =I9*L9*P9/100 -> 4
A10: 2 | B10: ='Ke Hoach'!B15 -> 0 | G10: ='Ke Hoach'!F15 -> 0 | H10: ='Ke Hoach'!G15 -> 0 | I10: ='Ke Hoach'!I15 -> 0 | J10: =G10*I10 -> 0 | M10: =IF(G10=0,0,MIN(L10,G10)*I10) -> 0 | O10: =I10*L10*N10/100 -> 0 | Q10: =I10*L10*P10/100 -> 0
A11: 3 | B11: ='Ke Hoach'!B16 -> 0 | G11: ='Ke Hoach'!F16 -> 0 | H11: ='Ke Hoach'!G16 -> 0 | I11: ='Ke Hoach'!I16 -> 0 | J11: =G11*I11 -> 0 | M11: =IF(G11=0,0,MIN(L11,G11)*I11) -> 0 | O11: =I11*L11*N11/100 -> 0 | Q11: =I11*L11*P11/100 -> 0
A12: 4 | B12: ='Ke Hoach'!B17 -> 0 | G12: ='Ke Hoach'!F17 -> 0 | H12: ='Ke Hoach'!G17 -> 0 | I12: ='Ke Hoach'!I17 -> 0 | J12: =G12*I12 -> 0 | M12: =IF(G12=0,0,MIN(L12,G12)*I12) -> 0 | O12: =I12*L12*N12/100 -> 0 | Q12: =I12*L12*P12/100 -> 0
A13: 5 | B13: ='Ke Hoach'!B18 -> 0 | G13: ='Ke Hoach'!F18 -> 0 | H13: ='Ke Hoach'!G18 -> 0 | I13: ='Ke Hoach'!I18 -> 0 | J13: =G13*I13 -> 0 | M13: =IF(G13=0,0,MIN(L13,G13)*I13) -> 0 | O13: =I13*L13*N13/100 -> 0 | Q13: =I13*L13*P13/100 -> 0
A14: 6 | B14: ='Ke Hoach'!B19 -> 0 | G14: ='Ke Hoach'!F19 -> 0 | H14: ='Ke Hoach'!G19 -> 0 | I14: ='Ke Hoach'!I19 -> 0 | J14: =G14*I14 -> 0 | M14: =IF(G14=0,0,MIN(L14,G14)*I14) -> 0 | O14: =I14*L14*N14/100 -> 0 | Q14: =I14*L14*P14/100 -> 0
A15: 7 | B15: ='Ke Hoach'!B20 -> 0 | G15: ='Ke Hoach'!F20 -> 0 | H15: ='Ke Hoach'!G20 -> 0 | I15: ='Ke Hoach'!I20 -> 0 | J15: =G15*I15 -> 0 | M15: =IF(G15=0,0,MIN(L15,G15)*I15) -> 0 | O15: =I15*L15*N15/100 -> 0 | Q15: =I15*L15*P15/100 -> 0
A16: 8 | B16: ='Ke Hoach'!B21 -> 0 | G16: ='Ke Hoach'!F21 -> 0 | H16: ='Ke Hoach'!G21 -> 0 | I16: ='Ke Hoach'!I21 -> 0 | J16: =G16*I16 -> 0 | M16: =IF(G16=0,0,MIN(L16,G16)*I16) -> 0 | O16: =I16*L16*N16/100 -> 0 | Q16: =I16*L16*P16/100 -> 0
A17: 9 | B17: ='Ke Hoach'!B22 -> 0 | G17: ='Ke Hoach'!F22 -> 0 | H17: ='Ke Hoach'!G22 -> 0 | I17: ='Ke Hoach'!I22 -> 0 | J17: =G17*I17 -> 0 | M17: =IF(G17=0,0,MIN(L17,G17)*I17) -> 0 | O17: =I17*L17*N17/100 -> 0 | Q17: =I17*L17*P17/100 -> 0
A18: 10 | B18: ='Ke Hoach'!B23 -> 0 | G18: ='Ke Hoach'!F23 -> 0 | H18: ='Ke Hoach'!G23 -> 0 | I18: ='Ke Hoach'!I23 -> 0 | J18: =G18*I18 -> 0 | M18: =IF(G18=0,0,MIN(L18,G18)*I18) -> 0 | O18: =I18*L18*N18/100 -> 0 | Q18: =I18*L18*P18/100 -> 0
A19: 11 | B19: ='Ke Hoach'!B24 -> 0 | G19: ='Ke Hoach'!F24 -> 0 | H19: ='Ke Hoach'!G24 -> 0 | I19: ='Ke Hoach'!I24 -> 0 | J19: =G19*I19 -> 0 | M19: =IF(G19=0,0,MIN(L19,G19)*I19) -> 0 | O19: =I19*L19*N19/100 -> 0 | Q19: =I19*L19*P19/100 -> 0
A20: 12 | B20: ='Ke Hoach'!B25 -> 0 | G20: ='Ke Hoach'!F25 -> 0 | H20: ='Ke Hoach'!G25 -> 0 | I20: ='Ke Hoach'!I25 -> 0 | J20: =G20*I20 -> 0 | M20: =IF(G20=0,0,MIN(L20,G20)*I20) -> 0 | O20: =I20*L20*N20/100 -> 0 | Q20: =I20*L20*P20/100 -> 0
A21: 13 | B21: ='Ke Hoach'!B26 -> 0 | G21: ='Ke Hoach'!F26 -> 0 | H21: ='Ke Hoach'!G26 -> 0 | I21: ='Ke Hoach'!I26 -> 0 | J21: =G21*I21 -> 0 | M21: =IF(G21=0,0,MIN(L21,G21)*I21) -> 0 | O21: =I21*L21*N21/100 -> 0 | Q21: =I21*L21*P21/100 -> 0
... A28: 20 | B28: ='Ke Hoach'!B33 -> 0 | G28: ='Ke Hoach'!F33 -> 0 | H28: ='Ke Hoach'!G33 -> 0 | I28: ='Ke Hoach'!I33 -> 0 | J28: =G28*I28 -> 0 | M28: =IF(G28=0,0,MIN(L28,G28)*I28) -> 0 | O28: =I28*L28*N28/100 -> 0 | Q28: =I28*L28*P28/100 -> 0
A29: II | B29: Trục (2) - Hoàn thiện thể chế, đẩy mạnh phân cấp, phân quyền gắn với kiểm tra, giám sát | J29: =SUM(J30:J49) -> 0 | M29: =SUM(M30:M49) -> 0 | O29: =SUM(O30:O49) -> 0 | Q29: =SUM(Q30:Q49) -> 0 | R29: =(M29+O29+Q29)/3 -> 0
A30: 1 | B30: ='Ke Hoach'!B35 -> 0 | G30: ='Ke Hoach'!F35 -> 0 | H30: ='Ke Hoach'!G35 -> 0 | I30: ='Ke Hoach'!I35 -> 0 | J30: =G30*I30 -> 0 | M30: =IF(G30=0,0,MIN(L30,G30)*I30) -> 0 | O30: =I30*L30*N30/100 -> 0 | Q30: =I30*L30*P30/100 -> 0
A31: 2 | B31: ='Ke Hoach'!B36 -> 0 | G31: ='Ke Hoach'!F36 -> 0 | H31: ='Ke Hoach'!G36 -> 0 | I31: ='Ke Hoach'!I36 -> 0 | J31: =G31*I31 -> 0 | M31: =IF(G31=0,0,MIN(L31,G31)*I31) -> 0 | O31: =I31*L31*N31/100 -> 0 | Q31: =I31*L31*P31/100 -> 0
A32: 3 | B32: ='Ke Hoach'!B37 -> 0 | G32: ='Ke Hoach'!F37 -> 0 | H32: ='Ke Hoach'!G37 -> 0 | I32: ='Ke Hoach'!I37 -> 0 | J32: =G32*I32 -> 0 | M32: =IF(G32=0,0,MIN(L32,G32)*I32) -> 0 | O32: =I32*L32*N32/100 -> 0 | Q32: =I32*L32*P32/100 -> 0
A33: 4 | B33: ='Ke Hoach'!B38 -> 0 | G33: ='Ke Hoach'!F38 -> 0 | H33: ='Ke Hoach'!G38 -> 0 | I33: ='Ke Hoach'!I38 -> 0 | J33: =G33*I33 -> 0 | M33: =IF(G33=0,0,MIN(L33,G33)*I33) -> 0 | O33: =I33*L33*N33/100 -> 0 | Q33: =I33*L33*P33/100 -> 0
A34: 5 | B34: ='Ke Hoach'!B39 -> 0 | G34: ='Ke Hoach'!F39 -> 0 | H34: ='Ke Hoach'!G39 -> 0 | I34: ='Ke Hoach'!I39 -> 0 | J34: =G34*I34 -> 0 | M34: =IF(G34=0,0,MIN(L34,G34)*I34) -> 0 | O34: =I34*L34*N34/100 -> 0 | Q34: =I34*L34*P34/100 -> 0
A35: 6 | B35: ='Ke Hoach'!B40 -> 0 | G35: ='Ke Hoach'!F40 -> 0 | H35: ='Ke Hoach'!G40 -> 0 | I35: ='Ke Hoach'!I40 -> 0 | J35: =G35*I35 -> 0 | M35: =IF(G35=0,0,MIN(L35,G35)*I35) -> 0 | O35: =I35*L35*N35/100 -> 0 | Q35: =I35*L35*P35/100 -> 0
A36: 7 | B36: ='Ke Hoach'!B41 -> 0 | G36: ='Ke Hoach'!F41 -> 0 | H36: ='Ke Hoach'!G41 -> 0 | I36: ='Ke Hoach'!I41 -> 0 | J36: =G36*I36 -> 0 | M36: =IF(G36=0,0,MIN(L36,G36)*I36) -> 0 | O36: =I36*L36*N36/100 -> 0 | Q36: =I36*L36*P36/100 -> 0
A37: 8 | B37: ='Ke Hoach'!B42 -> 0 | G37: ='Ke Hoach'!F42 -> 0 | H37: ='Ke Hoach'!G42 -> 0 | I37: ='Ke Hoach'!I42 -> 0 | J37: =G37*I37 -> 0 | M37: =IF(G37=0,0,MIN(L37,G37)*I37) -> 0 | O37: =I37*L37*N37/100 -> 0 | Q37: =I37*L37*P37/100 -> 0
A38: 9 | B38: ='Ke Hoach'!B43 -> 0 | G38: ='Ke Hoach'!F43 -> 0 | H38: ='Ke Hoach'!G43 -> 0 | I38: ='Ke Hoach'!I43 -> 0 | J38: =G38*I38 -> 0 | M38: =IF(G38=0,0,MIN(L38,G38)*I38) -> 0 | O38: =I38*L38*N38/100 -> 0 | Q38: =I38*L38*P38/100 -> 0
A39: 10 | B39: ='Ke Hoach'!B44 -> 0 | G39: ='Ke Hoach'!F44 -> 0 | H39: ='Ke Hoach'!G44 -> 0 | I39: ='Ke Hoach'!I44 -> 0 | J39: =G39*I39 -> 0 | M39: =IF(G39=0,0,MIN(L39,G39)*I39) -> 0 | O39: =I39*L39*N39/100 -> 0 | Q39: =I39*L39*P39/100 -> 0
A40: 11 | B40: ='Ke Hoach'!B45 -> 0 | G40: ='Ke Hoach'!F45 -> 0 | H40: ='Ke Hoach'!G45 -> 0 | I40: ='Ke Hoach'!I45 -> 0 | J40: =G40*I40 -> 0 | M40: =IF(G40=0,0,MIN(L40,G40)*I40) -> 0 | O40: =I40*L40*N40/100 -> 0 | Q40: =I40*L40*P40/100 -> 0
A41: 12 | B41: ='Ke Hoach'!B46 -> 0 | G41: ='Ke Hoach'!F46 -> 0 | H41: ='Ke Hoach'!G46 -> 0 | I41: ='Ke Hoach'!I46 -> 0 | J41: =G41*I41 -> 0 | M41: =IF(G41=0,0,MIN(L41,G41)*I41) -> 0 | O41: =I41*L41*N41/100 -> 0 | Q41: =I41*L41*P41/100 -> 0
... A49: 20 | B49: ='Ke Hoach'!B54 -> 0 | G49: ='Ke Hoach'!F54 -> 0 | H49: ='Ke Hoach'!G54 -> 0 | I49: ='Ke Hoach'!I54 -> 0 | J49: =G49*I49 -> 0 | M49: =IF(G49=0,0,MIN(L49,G49)*I49) -> 0 | O49: =I49*L49*N49/100 -> 0 | Q49: =I49*L49*P49/100 -> 0
A50: III | B50: Trục (3) - Thúc đẩy phát triển khoa học, công nghệ, đổi mới sáng tạo và chuyển đổi số | J50: =SUM(J51:J70) -> 0 | M50: =SUM(M51:M70) -> 0 | O50: =SUM(O51:O70) -> 0 | Q50: =SUM(Q51:Q70) -> 0 | R50: =(M50+O50+Q50)/3 -> 0
A51: 1 | B51: ='Ke Hoach'!B56 -> 0 | G51: ='Ke Hoach'!F56 -> 0 | H51: ='Ke Hoach'!G56 -> 0 | I51: ='Ke Hoach'!I56 -> 0 | J51: =G51*I51 -> 0 | M51: =IF(G51=0,0,MIN(L51,G51)*I51) -> 0 | O51: =I51*L51*N51/100 -> 0 | Q51: =I51*L51*P51/100 -> 0
A52: 2 | B52: ='Ke Hoach'!B57 -> 0 | G52: ='Ke Hoach'!F57 -> 0 | H52: ='Ke Hoach'!G57 -> 0 | I52: ='Ke Hoach'!I57 -> 0 | J52: =G52*I52 -> 0 | M52: =IF(G52=0,0,MIN(L52,G52)*I52) -> 0 | O52: =I52*L52*N52/100 -> 0 | Q52: =I52*L52*P52/100 -> 0
A53: 3 | B53: ='Ke Hoach'!B58 -> 0 | G53: ='Ke Hoach'!F58 -> 0 | H53: ='Ke Hoach'!G58 -> 0 | I53: ='Ke Hoach'!I58 -> 0 | J53: =G53*I53 -> 0 | M53: =IF(G53=0,0,MIN(L53,G53)*I53) -> 0 | O53: =I53*L53*N53/100 -> 0 | Q53: =I53*L53*P53/100 -> 0
...

Sheet Danh Gia
A2: Phụ lục V
A3: MẪU BẢN TỰ ĐÁNH GIÁ, XẾP LOẠI CÁ NHÂN QUÝ …. NĂM 2026 ĐỐI VỚI NHÀ GIÁO
A4: TRỰC TIẾP GIẢNG DẠY THUỘC BIÊN CHẾ CÁC KHOA CỦA TRƯỜNG CAO ĐẲNG KON TUM
A6: UBND TỈNH QUẢNG NGÃI | D6: CỘNG HÒA XÃ HỘI CHỦ NGHĨA VIỆT NAM
A7: TRƯỜNG CAO ĐẲNG KON TUM | D7: Độc lập - Tự do - Hạnh Phúc
A9: BẢNG TỰ ĐÁNH GIÁ, XẾP LOẠI CÁ NHÂN
A10: Quý: …. Năm: ….
A11: Họ và tên:…………………................................................. Ngày sinh: ……………….........................
A12: Chức vụ Đảng: ………………………….……………….………….............................................……….
A13: Chức vụ chính quyền: ………………..………………..……………..………………………………...............
A14: Chức vụ đoàn thể: ……………………..…………………………………………………………………………
A15: Đơn vị công tác: ………………………...………………………………………………………….………………
A17: I. Tự đánh giá kết quả thực hiện nhiệm vụ Trên cơ sở nhiệm vụ được giao, cá nhân tự đánh giá về kết quả thực hiện nhiệm vụ theo quý như sau:
A18: A | B18: NHÓM TIÊU CHÍ CHUNG (30 ĐIỂM)
A19: TT | B19: TIÊU CHÍ ĐÁNH GIÁ | D19: Điểm tối đa | E19: Điểm chấm (theo 4 mức) | F19: Ghi chú
A20: 1 | B20: Phẩm chất chính trị, phẩm chất đạo đức và ý thức kỷ luật, kỷ cương trong thực thi nhiệm vụ | D20: =SUM(D21:D30) -> 13 | E20: =SUM(E21:E30) -> 0 | F20: Hướng dẫn chấm: Mức 1 (Gương mẫu, không hạn chế): 90%-100% điểm tối đa Mức 2 (Đáp ứng đầy đủ, hạn chế nhỏ): 70%-dưới 90% Mức 3 (Có hạn chế, thiếu sót): 50%-dưới 70% Mức 4 (Hạn chế/vi phạm nghiêm trọng): dưới 50%, kể cả 0 điểm
A21: a) | B21: Chấp hành đường lối, chủ trương của Đảng, chính sách, pháp luật của Nhà nước và quy định của cơ quan, tổ chức, đơn vị. | D21: 2
A22: b) | B22: Có lập trường chính trị vững vàng; giữ gìn phẩm chất đạo đức, lối sống lành mạnh; không có biểu hiện suy thoái về tư tưởng chính trị, đạo đức, lối sống. | D22: 1
A23: c) | B23: Thực hiện đúng chuẩn mực đạo đức nghề nghiệp; trung thực, khách quan, công bằng trong thực hiện nhiệm vụ chuyên môn. | D23: 2
A24: d) | B24: Không tham nhũng, tiêu cực, lãng phí; không lợi dụng vị trí công tác để vụ lợi; không để người thân, người quen lợi dụng vị trí công tác của mình để trục lợi. | D24: 1
A25: đ) | B25: Có tinh thần đoàn kết, hợp tác trong công tác; tích cực tham gia các hoạt động tập thể, xây dựng môi trường làm việc chuyên nghiệp. | D25: 1
A26: e) | B26: Có tinh thần tự phê bình và phê bình; chủ động nhận diện hạn chế, khuyết điểm của bản thân và có biện pháp khắc phục. | D26: 1
A27: g) | B27: Chấp hành sự phân công của tổ chức; thực hiện đầy đủ chức trách, nhiệm vụ được giao. | D27: 2
A28: h) | B28: Thực hiện các quy định, quy chế, nội quy của cơ quan, tổ chức, đơn vị nơi công tác; phát huy trách nhiệm của cá nhân trong xây dựng tập thể cơ quan, tổ chức, đơn vị. | D28: 1
A29: i) | B29: Thực hiện việc kê khai và công khai tài sản, thu nhập theo quy định. | D29: 1
A30: k) | B30: Báo cáo đầy đủ, trung thực, cung cấp thông tin chính xác, khách quan về những nội dung liên quan đến việc thực hiện chức trách, nhiệm vụ được giao và hoạt động của cơ quan, tổ chức, đơn vị với cấp trên khi được yêu cầu. | D30: 1
A31: 2 | B31: Năng lực chuyên môn, nghiệp vụ theo yêu cầu của vị trí việc làm; tinh thần trách nhiệm trong thực thi nhiệm vụ; thái độ phục vụ người học, doanh nghiệp, đối tác; khả năng phối hợp trong công tác | D31: =SUM(D32:D35) -> 12 | E31: =SUM(E32:E35) -> 0
A32: a) | B32: Năng lực chuyên môn, nghiệp vụ theo yêu cầu của vị trí việc làm: Có kiến thức chuyên sâu, toàn diện về lĩnh vực công tác được phân công; hiểu biết đầy đủ về quy định pháp luật, quy trình nghiệp vụ có liên quan đến vị trí việc làm. Thường xuyên cập nhật kiến thức mới, có khả năng nghiên cứu, phân tích, tổng hợp và vận dụng sáng tạo vào công việc; đáp ứng yêu cầu đổi mới, cải cách hành chính. Có kỹ năng xử lý công việc độc lập, làm việc nhóm hiệu quả; sử dụng thành thạo công nghệ thông tin và các công cụ hỗ trợ phục vụ chuyên môn, nghiệp vụ. | D32: 3
A33: b) | B33: Khả năng đáp ứng yêu cầu thực thi nhiệm vụ được giao thường xuyên, đột xuất: Nhiệm vụ thường xuyên - Có khả năng vận dụng thành thạo kiến thức chuyên môn, nghiệp vụ để xử lý công việc chuyên môn theo kế hoạch định kỳ; duy trì ổn định chất lượng chuyên môn. Nhiệm vụ đột xuất - Chủ động đề xuất giải pháp, thực hiện hiệu quả các công việc phát sinh có tính chất chuyên môn cao; có khả năng phản ứng nhanh, chính xác với yêu cầu mới. | D33: 3
A34: c) | B34: Tinh thần trách nhiệm trong thực hiện nhiệm vụ: Có tinh thần trách nhiệm trong việc nghiên cứu, đề xuất, tham mưu nội dung chuyên môn; chủ động tiếp cận thông tin, kịp thời điều chỉnh cách làm để phù hợp với yêu cầu mới. Tích cực cập nhật, ứng dụng kiến thức, công nghệ mới trong công việc chuyên môn; có tinh thần cầu thị, phối hợp tốt trong các hoạt động liên quan đến chuyên môn. | D34: 3
A35: d) | B35: Thái độ phục vụ người sử dụng dịch vụ sự nghiệp công (người học) và các tổ chức, cá nhân có liên quan; khả năng phối hợp với đồng nghiệp: Có thái độ chuẩn mực, chuyên nghiệp trong cung cấp dịch vụ sự nghiệp công; bảo đảm công bằng, minh bạch, đúng quy định trong quá trình thực hiện nhiệm vụ. Có tinh thần hợp tác, phối hợp với đồng nghiệp và các đơn vị có liên quan trong thực hiện nhiệm vụ. | D35: 3
A36: 3 | B36: Năng lực đổi mới, sáng tạo; dám nghĩ, dám làm, dám chịu trách nhiệm vì lợi ích chung trong thực hiện nhiệm vụ | D36: =SUM(D37:D39) -> 5 | E36: =SUM(E37:E39) -> 0
A37: a) | B37: Có sản phẩm, giải pháp đột phá, sáng tạo đem lại giá trị, hiệu quả thiết thực, tác động tích cực đến kết quả thực hiện nhiệm vụ của tổ chức, đơn vị. | D37: 2
A38: b) | B38: Có tinh thần chịu trách nhiệm trước kết quả công việc; chủ động nhận trách nhiệm khi có sai sót và có biện pháp khắc phục rõ ràng, cụ thể. | D38: 2
A39: c) | B39: Chủ động đưa ra quyết định trong phạm vi thẩm quyền, không né tránh; có tinh thần tiên phong trong thực hiện những nhiệm vụ mới. | D39: 1
B40: Tổng điểm nhóm A | D40: =D20+D31+D36 -> 30 | E40: =E20+E31+E36 -> 0
A41: B | B41: KẾT QUẢ THỰC HIỆN NHIỆM VỤ ĐƯỢC GIAO (70 ĐIỂM) - Đề nghị đề xuất mức điểm tối đa đối với các nhiệm vụ trục chính (Lưu ý: Đối với viên chức không giữ chức vụ quản lý, 06 trục kết quả chỉ mang tính chất tham chiếu khi phù hợp, không bắt buộc áp dụng đủ cả 06 trục - Điều 12.2 Quy chế; đơn vị có thể điều chỉnh trọng số các trục 2-6 cho phù hợp với thực tế nhiệm vụ được giao.)
A42: TT | B42: Tiêu chí/Nội dung | C42: Mục tiêu, nhiệm vụ đề ra | D42: Kết quả sản phẩm thực tế | E42: Điểm KPI (%) | F42: Điểm tối đa | G42: Điểm đạt (= Điểm KPI x Điểm tối đa) | H42: Ghi chú
A43: 1 | B43: Trục (1) - Thực hiện mục tiêu phát triển Kinh tế - xã hội và nhiệm vụ chính trị được giao | C43: =KPI!J8 -> 5 | D43: =KPI!R8 -> 4 | E43: =IF(AND(C43<>0,D43<>0),D43*100/C43,0) -> 80 | F43: 40 | G43: =E43%*F43 -> 32
A44: 1.1 | B44: Thực hiện nhiệm vụ giảng dạy theo kế hoạch
...
